Workbook
Name USD_BDT: Settings!$B$5
Name RMB_BDT: Settings!$B$6
Name CUSTOMS_PCT: Settings!$B$7
Name MISC_FEE: Settings!$B$8
Name MARKUP_PCT: Settings!$B$9
Name MAX_PRICE: Settings!$B$10
Name HARD_REJECT_PRICE: Settings!$B$11
Name W_FEMININE: Settings!$B$12
Name W_TREND: Settings!$B$13
Name W_AESTHETIC: Settings!$B$14
Name W_STYLE: Settings!$B$15
Name W_LIGHT: Settings!$B$16
Name W_REELS: Settings!$B$17
Name W_GIFT: Settings!$B$18
Name W_PRICEFIT: Settings!$B$19
Name W_DEMAND: Settings!$B$20
Name W_QUALITY: Settings!$B$21
Name BUY_THRESHOLD: Settings!$B$22
Name MAYBE_THRESHOLD: Settings!$B$23
Name LIST_PLATFORM: 'Dropdown Lists'!$A$2:$A$7
Name LIST_CATEGORY: 'Dropdown Lists'!$B$2:$B$13
Name LIST_CURRENCY: 'Dropdown Lists'!$C$2:$C$4
Name LIST_DECISION: 'Dropdown Lists'!$D$2:$D$5
Name LIST_APPROVAL: 'Dropdown Lists'!$E$2:$E$5
Name LIST_SCORE: 'Dropdown Lists'!$F$2:$F$6

Sheet Product Tracker
A1: AAYNA Product Scout Lite — Product Tracker | I1: Reflect your everyday style — sourcing decisions, made together.
A2: SKU | B2: Date Added | C2: Product Name | D2: Product Image/Link | E2: Category | F2: Source Platform | G2: Source URL | H2: Supplier Name | I2: Unit Cost (Source Currency) | J2: Source Currency | K2: Unit Cost (BDT) | L2: Shipping Cost/Unit (BDT) | M2: Customs/Duty % | N2: Misc Fees/Unit (BDT) | O2: Estimated Landed Cost (BDT) | P2: Suggested Selling Price (BDT) | Q2: Expected Profit/Unit (BDT) | R2: Profit Margin % | S2: Feminine Score (1-5) | T2: Trend Score (1-5) | U2: AAYNA Aesthetic Fit Score (1-5) | V2: Easy to Style Score (1-5) | W2: Lightweight Score (1-5) | X2: Reels/Photo Potential Score (1-5) | Y2: Giftability Score (1-5) | Z2: Price Fit Score (1-5) | AA2: Demand Score (1-5) | AB2: Quality/Risk Score (1-5) | AC2: Total Product Score (/100) | AD2: Decision | AE2: Reason | AF2: Content/Reel Idea | AG2: Approval Status | AH2: Approved By | AI2: Date Decided | AJ2: Rank Key: Overall (hidden) | AK2: Rank Key: Under 700 BDT (hidden) | AL2: Rank Key: Reels/Photo (hidden) | AM2: Rank Key: Giftability (hidden) | AN2: Rank Key: Needs Review (hidden)
A3: =IF(C3="","","AYN-"&UPPER(LEFT(E3,3))&"-"&TEXT(ROW()-2,"000")) | B3: 2026-06-20 | C3: Antique Gold Hoop Earrings | D3: drive.google.com/sample1 | E3: Earrings | F3: AliExpress | G3: aliexpress.com/item/sample1 | H3: Lin Wei Trading | I3: 1.8 | J3: USD | K3: =IF(I3="","",IF(J3="BDT",I3,IF(J3="USD",I3*USD_BDT,IF(J3="RMB",I3*RMB_BDT,"")))) | L3: 25 | N3: 15 | O3: =IF(K3="","",K3+IFERROR(L3,0)+(K3*IF(M3="",CUSTOMS_PCT,M3))+IF(N3="",MISC_FEE,N3)) | P3: =IF(O3="","",ROUND(O3*(1+MARKUP_PCT),-1)-1) | Q3: =IF(P3="","",P3-O3) | R3: =IF(OR(P3="",P3=0),"",Q3/P3) | S3: 5 | T3: 5 | U3: 5 | V3: 4 | W3: 5 | X3: 5 | Y3: 4 | Z3: 5 | AA3: 4 | AB3: 5 | AC3: =IF(COUNT(S3:AB3)<10,"",(S3*W_FEMININE+T3*W_TREND+U3*W_AESTHETIC+V3*W_STYLE+W3*W_LIGHT+X3*W_REELS+Y3*W_GIFT+Z3*W_PRICEFIT+AA3*W_DEMAND+AB3*W_QUALITY)/5*100) | AD3: =IF(P3="","",IF(P3>HARD_REJECT_PRICE,"Reject",IF(P3>MAX_PRICE,"Price Review",IF(AC3="","",IF(AND(AC3>=BUY_THRESHOLD,OR(AB3<=2,U3<=2)),"Maybe",IF(AC3>=BUY_THRESHOLD,"Buy",IF(AC3>=MAYBE_THRESHOLD,"Maybe","Reject"))))))) | AE3: Strong rose-gold match, trending on TikTok, lightweight and giftable. | AF3: Reel: 'Get Ready With Me' earring swap, 3 looks in 15 sec. | AG3: Approved | AH3: Nadia | AI3: 2026-06-21 | AJ3: =IF(AC3="",-9999-ROW()*0.0000001,AC3-ROW()*0.0000001) | AK3: =IF(OR(AC3="",P3="",P3>MAX_PRICE),-9999-ROW()*0.0000001,AC3-ROW()*0.0000001) | AL3: =IF(AC3="",-9999-ROW()*0.0000001,X3*1000+AC3-ROW()*0.0000001) | AM3: =IF(AC3="",-9999-ROW()*0.0000001,Y3*1000+AC3-ROW()*0.0000001) | AN3: =IF(AND(OR(AD3="Maybe",AD3="Price Review"),AG3<>"Approved",AG3<>"Rejected"),IF(AC3="",0,AC3)-ROW()*0.0000001,-9999-ROW()*0.0000001)
A4: =IF(C4="","","AYN-"&UPPER(LEFT(E4,3))&"-"&TEXT(ROW()-2,"000")) | B4: 2026-06-21 | C4: Beaded Choker Necklace | D4: drive.google.com/sample2 | E4: Necklace | F4: SkyBuyBD | G4: skybuybd.com/item/sample2 | H4: Skybuy Supplier 14 | I4: 60 | J4: BDT | K4: =IF(I4="","",IF(J4="BDT",I4,IF(J4="USD",I4*USD_BDT,IF(J4="RMB",I4*RMB_BDT,"")))) | L4: 10 | N4: 12 | O4: =IF(K4="","",K4+IFERROR(L4,0)+(K4*IF(M4="",CUSTOMS_PCT,M4))+IF(N4="",MISC_FEE,N4)) | P4: =IF(O4="","",ROUND(O4*(1+MARKUP_PCT),-1)-1) | Q4: =IF(P4="","",P4-O4) | R4: =IF(OR(P4="",P4=0),"",Q4/P4) | S4: 5 | T4: 4 | U4: 5 | V4: 4 | W4: 4 | X4: 4 | Y4: 4 | Z4: 5 | AA4: 4 | AB4: 2 | AC4: =IF(COUNT(S4:AB4)<10,"",(S4*W_FEMININE+T4*W_TREND+U4*W_AESTHETIC+V4*W_STYLE+W4*W_LIGHT+X4*W_REELS+Y4*W_GIFT+Z4*W_PRICEFIT+AA4*W_DEMAND+AB4*W_QUALITY)/5*100) | AD4: =IF(P4="","",IF(P4>HARD_REJECT_PRICE,"Reject",IF(P4>MAX_PRICE,"Price Review",IF(AC4="","",IF(AND(AC4>=BUY_THRESHOLD,OR(AB4<=2,U4<=2)),"Maybe",IF(AC4>=BUY_THRESHOLD,"Buy",IF(AC4>=MAYBE_THRESHOLD,"Maybe","Reject"))))))) | AE4: Gorgeous and on-trend, but beads chip easily in transit — quality/return risk caps this at Maybe. | AF4: Try-on reel layering 3 chokers. | AG4: Pending | AJ4: =IF(AC4="",-9999-ROW()*0.0000001,AC4-ROW()*0.0000001) | AK4: =IF(OR(AC4="",P4="",P4>MAX_PRICE),-9999-ROW()*0.0000001,AC4-ROW()*0.0000001) | AL4: =IF(AC4="",-9999-ROW()*0.0000001,X4*1000+AC4-ROW()*0.0000001) | AM4: =IF(AC4="",-9999-ROW()*0.0000001,Y4*1000+AC4-ROW()*0.0000001) | AN4: =IF(AND(OR(AD4="Maybe",AD4="Price Review"),AG4<>"Approved",AG4<>"Rejected"),IF(AC4="",0,AC4)-ROW()*0.0000001,-9999-ROW()*0.0000001)
A5: =IF(C5="","","AYN-"&UPPER(LEFT(E5,3))&"-"&TEXT(ROW()-2,"000")) | B5: 2026-06-21 | C5: Plain Plastic Hair Clip | D5: drive.google.com/sample3 | E5: Hair Accessory | F5: 1688 | G5: 1688.com/item/sample3 | H5: Generic Factory 8 | I5: 25 | J5: BDT | K5: =IF(I5="","",IF(J5="BDT",I5,IF(J5="USD",I5*USD_BDT,IF(J5="RMB",I5*RMB_BDT,"")))) | L5: 8 | N5: 10 | O5: =IF(K5="","",K5+IFERROR(L5,0)+(K5*IF(M5="",CUSTOMS_PCT,M5))+IF(N5="",MISC_FEE,N5)) | P5: =IF(O5="","",ROUND(O5*(1+MARKUP_PCT),-1)-1) | Q5: =IF(P5="","",P5-O5) | R5: =IF(OR(P5="",P5=0),"",Q5/P5) | S5: 2 | T5: 2 | U5: 2 | V5: 3 | W5: 3 | X5: 2 | Y5: 2 | Z5: 4 | AA5: 2 | AB5: 3 | AC5: =IF(COUNT(S5:AB5)<10,"",(S5*W_FEMININE+T5*W_TREND+U5*W_AESTHETIC+V5*W_STYLE+W5*W_LIGHT+X5*W_REELS+Y5*W_GIFT+Z5*W_PRICEFIT+AA5*W_DEMAND+AB5*W_QUALITY)/5*100) | AD5: =IF(P5="","",IF(P5>HARD_REJECT_PRICE,"Reject",IF(P5>MAX_PRICE,"Price Review",IF(AC5="","",IF(AND(AC5>=BUY_THRESHOLD,OR(AB5<=2,U5<=2)),"Maybe",IF(AC5>=BUY_THRESHOLD,"Buy",IF(AC5>=MAYBE_THRESHOLD,"Maybe","Reject"))))))) | AE5: Generic look, low trend/demand/aesthetic fit — total score too low to justify stocking. | AG5: Rejected | AJ5: =IF(AC5="",-9999-ROW()*0.0000001,AC5-ROW()*0.0000001) | AK5: =IF(OR(AC5="",P5="",P5>MAX_PRICE),-9999-ROW()*0.0000001,AC5-ROW()*0.0000001) | AL5: =IF(AC5="",-9999-ROW()*0.0000001,X5*1000+AC5-ROW()*0.0000001) | AM5: =IF(AC5="",-9999-ROW()*0.0000001,Y5*1000+AC5-ROW()*0.0000001) | AN5: =IF(AND(OR(AD5="Maybe",AD5="Price Review"),AG5<>"Approved",AG5<>"Rejected"),IF(AC5="",0,AC5)-ROW()*0.0000001,-9999-ROW()*0.0000001)
A6: =IF(C6="","","AYN-"&UPPER(LEFT(E6,3))&"-"&TEXT(ROW()-2,"000")) | B6: 2026-06-22 | C6: Embroidered Tote Bag | D6: drive.google.com/sample4 | E6: Bag | F6: AliExpress | G6: aliexpress.com/item/sample4 | H6: Lin Wei Trading | I6: 300 | J6: BDT | K6: =IF(I6="","",IF(J6="BDT",I6,IF(J6="USD",I6*USD_BDT,IF(J6="RMB",I6*RMB_BDT,"")))) | L6: 40 | N6: 15 | O6: =IF(K6="","",K6+IFERROR(L6,0)+(K6*IF(M6="",CUSTOMS_PCT,M6))+IF(N6="",MISC_FEE,N6)) | P6: =IF(O6="","",ROUND(O6*(1+MARKUP_PCT),-1)-1) | Q6: =IF(P6="","",P6-O6) | R6: =IF(OR(P6="",P6=0),"",Q6/P6) | S6: 4 | T6: 4 | U6: 4 | V6: 3 | W6: 3 | X6: 3 | Y6: 4 | Z6: 2 | AA6: 4 | AB6: 4 | AC6: =IF(COUNT(S6:AB6)<10,"",(S6*W_FEMININE+T6*W_TREND+U6*W_AESTHETIC+V6*W_STYLE+W6*W_LIGHT+X6*W_REELS+Y6*W_GIFT+Z6*W_PRICEFIT+AA6*W_DEMAND+AB6*W_QUALITY)/5*100) | AD6: =IF(P6="","",IF(P6>HARD_REJECT_PRICE,"Reject",IF(P6>MAX_PRICE,"Price Review",IF(AC6="","",IF(AND(AC6>=BUY_THRESHOLD,OR(AB6<=2,U6<=2)),"Maybe",IF(AC6>=BUY_THRESHOLD,"Buy",IF(AC6>=MAYBE_THRESHOLD,"Maybe","Reject"))))))) | AE6: Lovely design, but landed cost pushes selling price over 700 — needs supplier price negotiation. | AF6: Flatlay reel with 3 outfit pairings. | AG6: Pending | AJ6: =IF(AC6="",-9999-ROW()*0.0000001,AC6-ROW()*0.0000001) | AK6: =IF(OR(AC6="",P6="",P6>MAX_PRICE),-9999-ROW()*0.0000001,AC6-ROW()*0.0000001) | AL6: =IF(AC6="",-9999-ROW()*0.0000001,X6*1000+AC6-ROW()*0.0000001) | AM6: =IF(AC6="",-9999-ROW()*0.0000001,Y6*1000+AC6-ROW()*0.0000001) | AN6: =IF(AND(OR(AD6="Maybe",AD6="Price Review"),AG6<>"Approved",AG6<>"Rejected"),IF(AC6="",0,AC6)-ROW()*0.0000001,-9999-ROW()*0.0000001)
A7: =IF(C7="","","AYN-"&UPPER(LEFT(E7,3))&"-"&TEXT(ROW()-2,"000")) | B7: 2026-06-22 | C7: Designer-Inspired Sunglasses | D7: drive.google.com/sample5 | E7: Sunglasses | F7: AliExpress | G7: aliexpress.com/item/sample5 | H7: Guangzhou Eyewear Co | I7: 15 | J7: USD | K7: =IF(I7="","",IF(J7="BDT",I7,IF(J7="USD",I7*USD_BDT,IF(J7="RMB",I7*RMB_BDT,"")))) | L7: 50 | N7: 15 | O7: =IF(K7="","",K7+IFERROR(L7,0)+(K7*IF(M7="",CUSTOMS_PCT,M7))+IF(N7="",MISC_FEE,N7)) | P7: =IF(O7="","",ROUND(O7*(1+MARKUP_PCT),-1)-1) | Q7: =IF(P7="","",P7-O7) | R7: =IF(OR(P7="",P7=0),"",Q7/P7) | AC7: =IF(COUNT(S7:AB7)<10,"",(S7*W_FEMININE+T7*W_TREND+U7*W_AESTHETIC+V7*W_STYLE+W7*W_LIGHT+X7*W_REELS+Y7*W_GIFT+Z7*W_PRICEFIT+AA7*W_DEMAND+AB7*W_QUALITY)/5*100) | AD7: =IF(P7="","",IF(P7>HARD_REJECT_PRICE,"Reject",IF(P7>MAX_PRICE,"Price Review",IF(AC7="","",IF(AND(AC7>=BUY_THRESHOLD,OR(AB7<=2,U7<=2)),"Maybe",IF(AC7>=BUY_THRESHOLD,"Buy",IF(AC7>=MAYBE_THRESHOLD,"Maybe","Reject"))))))) | AE7: Cost alone puts this far above our price ceiling even before scoring — auto-rejected. | AG7: Rejected | AJ7: =IF(AC7="",-9999-ROW()*0.0000001,AC7-ROW()*0.0000001) | AK7: =IF(OR(AC7="",P7="",P7>MAX_PRICE),-9999-ROW()*0.0000001,AC7-ROW()*0.0000001) | AL7: =IF(AC7="",-9999-ROW()*0.0000001,X7*1000+AC7-ROW()*0.0000001) | AM7: =IF(AC7="",-9999-ROW()*0.0000001,Y7*1000+AC7-ROW()*0.0000001) | AN7: =IF(AND(OR(AD7="Maybe",AD7="Price Review"),AG7<>"Approved",AG7<>"Rejected"),IF(AC7="",0,AC7)-ROW()*0.0000001,-9999-ROW()*0.0000001)
A8: =IF(C8="","","AYN-"&UPPER(LEFT(E8,3))&"-"&TEXT(ROW()-2,"000")) | K8: =IF(I8="","",IF(J8="BDT",I8,IF(J8="USD",I8*USD_BDT,IF(J8="RMB",I8*RMB_BDT,"")))) | O8: =IF(K8="","",K8+IFERROR(L8,0)+(K8*IF(M8="",CUSTOMS_PCT,M8))+IF(N8="",MISC_FEE,N8)) | P8: =IF(O8="","",ROUND(O8*(1+MARKUP_PCT),-1)-1) | Q8: =IF(P8="","",P8-O8) | R8: =IF(OR(P8="",P8=0),"",Q8/P8) | AC8: =IF(COUNT(S8:AB8)<10,"",(S8*W_FEMININE+T8*W_TREND+U8*W_AESTHETIC+V8*W_STYLE+W8*W_LIGHT+X8*W_REELS+Y8*W_GIFT+Z8*W_PRICEFIT+AA8*W_DEMAND+AB8*W_QUALITY)/5*100) | AD8: =IF(P8="","",IF(P8>HARD_REJECT_PRICE,"Reject",IF(P8>MAX_PRICE,"Price Review",IF(AC8="","",IF(AND(AC8>=BUY_THRESHOLD,OR(AB8<=2,U8<=2)),"Maybe",IF(AC8>=BUY_THRESHOLD,"Buy",IF(AC8>=MAYBE_THRESHOLD,"Maybe","Reject"))))))) | AJ8: =IF(AC8="",-9999-ROW()*0.0000001,AC8-ROW()*0.0000001) | AK8: =IF(OR(AC8="",P8="",P8>MAX_PRICE),-9999-ROW()*0.0000001,AC8-ROW()*0.0000001) | AL8: =IF(AC8="",-9999-ROW()*0.0000001,X8*1000+AC8-ROW()*0.0000001) | AM8: =IF(AC8="",-9999-ROW()*0.0000001,Y8*1000+AC8-ROW()*0.0000001) | AN8: =IF(AND(OR(AD8="Maybe",AD8="Price Review"),AG8<>"Approved",AG8<>"Rejected"),IF(AC8="",0,AC8)-ROW()*0.0000001,-9999-ROW()*0.0000001)
A9: =IF(C9="","","AYN-"&UPPER(LEFT(E9,3))&"-"&TEXT(ROW()-2,"000")) | K9: =IF(I9="","",IF(J9="BDT",I9,IF(J9="USD",I9*USD_BDT,IF(J9="RMB",I9*RMB_BDT,"")))) | O9: =IF(K9="","",K9+IFERROR(L9,0)+(K9*IF(M9="",CUSTOMS_PCT,M9))+IF(N9="",MISC_FEE,N9)) | P9: =IF(O9="","",ROUND(O9*(1+MARKUP_PCT),-1)-1) | Q9: =IF(P9="","",P9-O9) | R9: =IF(OR(P9="",P9=0),"",Q9/P9) | AC9: =IF(COUNT(S9:AB9)<10,"",(S9*W_FEMININE+T9*W_TREND+U9*W_AESTHETIC+V9*W_STYLE+W9*W_LIGHT+X9*W_REELS+Y9*W_GIFT+Z9*W_PRICEFIT+AA9*W_DEMAND+AB9*W_QUALITY)/5*100) | AD9: =IF(P9="","",IF(P9>HARD_REJECT_PRICE,"Reject",IF(P9>MAX_PRICE,"Price Review",IF(AC9="","",IF(AND(AC9>=BUY_THRESHOLD,OR(AB9<=2,U9<=2)),"Maybe",IF(AC9>=BUY_THRESHOLD,"Buy",IF(AC9>=MAYBE_THRESHOLD,"Maybe","Reject"))))))) | AJ9: =IF(AC9="",-9999-ROW()*0.0000001,AC9-ROW()*0.0000001) | AK9: =IF(OR(AC9="",P9="",P9>MAX_PRICE),-9999-ROW()*0.0000001,AC9-ROW()*0.0000001) | AL9: =IF(AC9="",-9999-ROW()*0.0000001,X9*1000+AC9-ROW()*0.0000001) | AM9: =IF(AC9="",-9999-ROW()*0.0000001,Y9*1000+AC9-ROW()*0.0000001) | AN9: =IF(AND(OR(AD9="Maybe",AD9="Price Review"),AG9<>"Approved",AG9<>"Rejected"),IF(AC9="",0,AC9)-ROW()*0.0000001,-9999-ROW()*0.0000001)
A10: =IF(C10="","","AYN-"&UPPER(LEFT(E10,3))&"-"&TEXT(ROW()-2,"000")) | K10: =IF(I10="","",IF(J10="BDT",I10,IF(J10="USD",I10*USD_BDT,IF(J10="RMB",I10*RMB_BDT,"")))) | O10: =IF(K10="","",K10+IFERROR(L10,0)+(K10*IF(M10="",CUSTOMS_PCT,M10))+IF(N10="",MISC_FEE,N10)) | P10: =IF(O10="","",ROUND(O10*(1+MARKUP_PCT),-1)-1) | Q10: =IF(P10="","",P10-O10) | R10: =IF(OR(P10="",P10=0),"",Q10/P10) | AC10: =IF(COUNT(S10:AB10)<10,"",(S10*W_FEMININE+T10*W_TREND+U10*W_AESTHETIC+V10*W_STYLE+W10*W_LIGHT+X10*W_REELS+Y10*W_GIFT+Z10*W_PRICEFIT+AA10*W_DEMAND+AB10*W_QUALITY)/5*100) | AD10: =IF(P10="","",IF(P10>HARD_REJECT_PRICE,"Reject",IF(P10>MAX_PRICE,"Price Review",IF(AC10="","",IF(AND(AC10>=BUY_THRESHOLD,OR(AB10<=2,U10<=2)),"Maybe",IF(AC10>=BUY_THRESHOLD,"Buy",IF(AC10>=MAYBE_THRESHOLD,"Maybe","Reject"))))))) | AJ10: =IF(AC10="",-9999-ROW()*0.0000001,AC10-ROW()*0.0000001) | AK10: =IF(OR(AC10="",P10="",P10>MAX_PRICE),-9999-ROW()*0.0000001,AC10-ROW()*0.0000001) | AL10: =IF(AC10="",-9999-ROW()*0.0000001,X10*1000+AC10-ROW()*0.0000001) | AM10: =IF(AC10="",-9999-ROW()*0.0000001,Y10*1000+AC10-ROW()*0.0000001) | AN10: =IF(AND(OR(AD10="Maybe",AD10="Price Review"),AG10<>"Approved",AG10<>"Rejected"),IF(AC10="",0,AC10)-ROW()*0.0000001,-9999-ROW()*0.0000001)
A11: =IF(C11="","","AYN-"&UPPER(LEFT(E11,3))&"-"&TEXT(ROW()-2,"000")) | K11: =IF(I11="","",IF(J11="BDT",I11,IF(J11="USD",I11*USD_BDT,IF(J11="RMB",I11*RMB_BDT,"")))) | O11: =IF(K11="","",K11+IFERROR(L11,0)+(K11*IF(M11="",CUSTOMS_PCT,M11))+IF(N11="",MISC_FEE,N11)) | P11: =IF(O11="","",ROUND(O11*(1+MARKUP_PCT),-1)-1) | Q11: =IF(P11="","",P11-O11) | R11: =IF(OR(P11="",P11=0),"",Q11/P11) | AC11: =IF(COUNT(S11:AB11)<10,"",(S11*W_FEMININE+T11*W_TREND+U11*W_AESTHETIC+V11*W_STYLE+W11*W_LIGHT+X11*W_REELS+Y11*W_GIFT+Z11*W_PRICEFIT+AA11*W_DEMAND+AB11*W_QUALITY)/5*100) | AD11: =IF(P11="","",IF(P11>HARD_REJECT_PRICE,"Reject",IF(P11>MAX_PRICE,"Price Review",IF(AC11="","",IF(AND(AC11>=BUY_THRESHOLD,OR(AB11<=2,U11<=2)),"Maybe",IF(AC11>=BUY_THRESHOLD,"Buy",IF(AC11>=MAYBE_THRESHOLD,"Maybe","Reject"))))))) | AJ11: =IF(AC11="",-9999-ROW()*0.0000001,AC11-ROW()*0.0000001) | AK11: =IF(OR(AC11="",P11="",P11>MAX_PRICE),-9999-ROW()*0.0000001,AC11-ROW()*0.0000001) | AL11: =IF(AC11="",-9999-ROW()*0.0000001,X11*1000+AC11-ROW()*0.0000001) | AM11: =IF(AC11="",-9999-ROW()*0.0000001,Y11*1000+AC11-ROW()*0.0000001) | AN11: =IF(AND(OR(AD11="Maybe",AD11="Price Review"),AG11<>"Approved",AG11<>"Rejected"),IF(AC11="",0,AC11)-ROW()*0.0000001,-9999-ROW()*0.0000001)
A12: =IF(C12="","","AYN-"&UPPER(LEFT(E12,3))&"-"&TEXT(ROW()-2,"000")) | K12: =IF(I12="","",IF(J12="BDT",I12,IF(J12="USD",I12*USD_BDT,IF(J12="RMB",I12*RMB_BDT,"")))) | O12: =IF(K12="","",K12+IFERROR(L12,0)+(K12*IF(M12="",CUSTOMS_PCT,M12))+IF(N12="",MISC_FEE,N12)) | P12: =IF(O12="","",ROUND(O12*(1+MARKUP_PCT),-1)-1) | Q12: =IF(P12="","",P12-O12) | R12: =IF(OR(P12="",P12=0),"",Q12/P12) | AC12: =IF(COUNT(S12:AB12)<10,"",(S12*W_FEMININE+T12*W_TREND+U12*W_AESTHETIC+V12*W_STYLE+W12*W_LIGHT+X12*W_REELS+Y12*W_GIFT+Z12*W_PRICEFIT+AA12*W_DEMAND+AB12*W_QUALITY)/5*100) | AD12: =IF(P12="","",IF(P12>HARD_REJECT_PRICE,"Reject",IF(P12>MAX_PRICE,"Price Review",IF(AC12="","",IF(AND(AC12>=BUY_THRESHOLD,OR(AB12<=2,U12<=2)),"Maybe",IF(AC12>=BUY_THRESHOLD,"Buy",IF(AC12>=MAYBE_THRESHOLD,"Maybe","Reject"))))))) | AJ12: =IF(AC12="",-9999-ROW()*0.0000001,AC12-ROW()*0.0000001) | AK12: =IF(OR(AC12="",P12="",P12>MAX_PRICE),-9999-ROW()*0.0000001,AC12-ROW()*0.0000001) | AL12: =IF(AC12="",-9999-ROW()*0.0000001,X12*1000+AC12-ROW()*0.0000001) | AM12: =IF(AC12="",-9999-ROW()*0.0000001,Y12*1000+AC12-ROW()*0.0000001) | AN12: =IF(AND(OR(AD12="Maybe",AD12="Price Review"),AG12<>"Approved",AG12<>"Rejected"),IF(AC12="",0,AC12)-ROW()*0.0000001,-9999-ROW()*0.0000001)
A13: =IF(C13="","","AYN-"&UPPER(LEFT(E13,3))&"-"&TEXT(ROW()-2,"000")) | K13: =IF(I13="","",IF(J13="BDT",I13,IF(J13="USD",I13*USD_BDT,IF(J13="RMB",I13*RMB_BDT,"")))) | O13: =IF(K13="","",K13+IFERROR(L13,0)+(K13*IF(M13="",CUSTOMS_PCT,M13))+IF(N13="",MISC_FEE,N13)) | P13: =IF(O13="","",ROUND(O13*(1+MARKUP_PCT),-1)-1) | Q13: =IF(P13="","",P13-O13) | R13: =IF(OR(P13="",P13=0),"",Q13/P13) | AC13: =IF(COUNT(S13:AB13)<10,"",(S13*W_FEMININE+T13*W_TREND+U13*W_AESTHETIC+V13*W_STYLE+W13*W_LIGHT+X13*W_REELS+Y13*W_GIFT+Z13*W_PRICEFIT+AA13*W_DEMAND+AB13*W_QUALITY)/5*100) | AD13: =IF(P13="","",IF(P13>HARD_REJECT_PRICE,"Reject",IF(P13>MAX_PRICE,"Price Review",IF(AC13="","",IF(AND(AC13>=BUY_THRESHOLD,OR(AB13<=2,U13<=2)),"Maybe",IF(AC13>=BUY_THRESHOLD,"Buy",IF(AC13>=MAYBE_THRESHOLD,"Maybe","Reject"))))))) | AJ13: =IF(AC13="",-9999-ROW()*0.0000001,AC13-ROW()*0.0000001) | AK13: =IF(OR(AC13="",P13="",P13>MAX_PRICE),-9999-ROW()*0.0000001,AC13-ROW()*0.0000001) | AL13: =IF(AC13="",-9999-ROW()*0.0000001,X13*1000+AC13-ROW()*0.0000001) | AM13: =IF(AC13="",-9999-ROW()*0.0000001,Y13*1000+AC13-ROW()*0.0000001) | AN13: =IF(AND(OR(AD13="Maybe",AD13="Price Review"),AG13<>"Approved",AG13<>"Rejected"),IF(AC13="",0,AC13)-ROW()*0.0000001,-9999-ROW()*0.0000001)
A14: =IF(C14="","","AYN-"&UPPER(LEFT(E14,3))&"-"&TEXT(ROW()-2,"000")) | K14: =IF(I14="","",IF(J14="BDT",I14,IF(J14="USD",I14*USD_BDT,IF(J14="RMB",I14*RMB_BDT,"")))) | O14: =IF(K14="","",K14+IFERROR(L14,0)+(K14*IF(M14="",CUSTOMS_PCT,M14))+IF(N14="",MISC_FEE,N14)) | P14: =IF(O14="","",ROUND(O14*(1+MARKUP_PCT),-1)-1) | Q14: =IF(P14="","",P14-O14) | R14: =IF(OR(P14="",P14=0),"",Q14/P14) | AC14: =IF(COUNT(S14:AB14)<10,"",(S14*W_FEMININE+T14*W_TREND+U14*W_AESTHETIC+V14*W_STYLE+W14*W_LIGHT+X14*W_REELS+Y14*W_GIFT+Z14*W_PRICEFIT+AA14*W_DEMAND+AB14*W_QUALITY)/5*100) | AD14: =IF(P14="","",IF(P14>HARD_REJECT_PRICE,"Reject",IF(P14>MAX_PRICE,"Price Review",IF(AC14="","",IF(AND(AC14>=BUY_THRESHOLD,OR(AB14<=2,U14<=2)),"Maybe",IF(AC14>=BUY_THRESHOLD,"Buy",IF(AC14>=MAYBE_THRESHOLD,"Maybe","Reject"))))))) | AJ14: =IF(AC14="",-9999-ROW()*0.0000001,AC14-ROW()*0.0000001) | AK14: =IF(OR(AC14="",P14="",P14>MAX_PRICE),-9999-ROW()*0.0000001,AC14-ROW()*0.0000001) | AL14: =IF(AC14="",-9999-ROW()*0.0000001,X14*1000+AC14-ROW()*0.0000001) | AM14: =IF(AC14="",-9999-ROW()*0.0000001,Y14*1000+AC14-ROW()*0.0000001) | AN14: =IF(AND(OR(AD14="Maybe",AD14="Price Review"),AG14<>"Approved",AG14<>"Rejected"),IF(AC14="",0,AC14)-ROW()*0.0000001,-9999-ROW()*0.0000001)
A15: =IF(C15="","","AYN-"&UPPER(LEFT(E15,3))&"-"&TEXT(ROW()-2,"000")) | K15: =IF(I15="","",IF(J15="BDT",I15,IF(J15="USD",I15*USD_BDT,IF(J15="RMB",I15*RMB_BDT,"")))) | O15: =IF(K15="","",K15+IFERROR(L15,0)+(K15*IF(M15="",CUSTOMS_PCT,M15))+IF(N15="",MISC_FEE,N15)) | P15: =IF(O15="","",ROUND(O15*(1+MARKUP_PCT),-1)-1) | Q15: =IF(P15="","",P15-O15) | R15: =IF(OR(P15="",P15=0),"",Q15/P15) | AC15: =IF(COUNT(S15:AB15)<10,"",(S15*W_FEMININE+T15*W_TREND+U15*W_AESTHETIC+V15*W_STYLE+W15*W_LIGHT+X15*W_REELS+Y15*W_GIFT+Z15*W_PRICEFIT+AA15*W_DEMAND+AB15*W_QUALITY)/5*100) | AD15: =IF(P15="","",IF(P15>HARD_REJECT_PRICE,"Reject",IF(P15>MAX_PRICE,"Price Review",IF(AC15="","",IF(AND(AC15>=BUY_THRESHOLD,OR(AB15<=2,U15<=2)),"Maybe",IF(AC15>=BUY_THRESHOLD,"Buy",IF(AC15>=MAYBE_THRESHOLD,"Maybe","Reject"))))))) | AJ15: =IF(AC15="",-9999-ROW()*0.0000001,AC15-ROW()*0.0000001) | AK15: =IF(OR(AC15="",P15="",P15>MAX_PRICE),-9999-ROW()*0.0000001,AC15-ROW()*0.0000001) | AL15: =IF(AC15="",-9999-ROW()*0.0000001,X15*1000+AC15-ROW()*0.0000001) | AM15: =IF(AC15="",-9999-ROW()*0.0000001,Y15*1000+AC15-ROW()*0.0000001) | AN15: =IF(AND(OR(AD15="Maybe",AD15="Price Review"),AG15<>"Approved",AG15<>"Rejected"),IF(AC15="",0,AC15)-ROW()*0.0000001,-9999-ROW()*0.0000001)
A16: =IF(C16="","","AYN-"&UPPER(LEFT(E16,3))&"-"&TEXT(ROW()-2,"000")) | K16: =IF(I16="","",IF(J16="BDT",I16,IF(J16="USD",I16*USD_BDT,IF(J16="RMB",I16*RMB_BDT,"")))) | O16: =IF(K16="","",K16+IFERROR(L16,0)+(K16*IF(M16="",CUSTOMS_PCT,M16))+IF(N16="",MISC_FEE,N16)) | P16: =IF(O16="","",ROUND(O16*(1+MARKUP_PCT),-1)-1) | Q16: =IF(P16="","",P16-O16) | R16: =IF(OR(P16="",P16=0),"",Q16/P16) | AC16: =IF(COUNT(S16:AB16)<10,"",(S16*W_FEMININE+T16*W_TREND+U16*W_AESTHETIC+V16*W_STYLE+W16*W_LIGHT+X16*W_REELS+Y16*W_GIFT+Z16*W_PRICEFIT+AA16*W_DEMAND+AB16*W_QUALITY)/5*100) | AD16: =IF(P16="","",IF(P16>HARD_REJECT_PRICE,"Reject",IF(P16>MAX_PRICE,"Price Review",IF(AC16="","",IF(AND(AC16>=BUY_THRESHOLD,OR(AB16<=2,U16<=2)),"Maybe",IF(AC16>=BUY_THRESHOLD,"Buy",IF(AC16>=MAYBE_THRESHOLD,"Maybe","Reject"))))))) | AJ16: =IF(AC16="",-9999-ROW()*0.0000001,AC16-ROW()*0.0000001) | AK16: =IF(OR(AC16="",P16="",P16>MAX_PRICE),-9999-ROW()*0.0000001,AC16-ROW()*0.0000001) | AL16: =IF(AC16="",-9999-ROW()*0.0000001,X16*1000+AC16-ROW()*0.0000001) | AM16: =IF(AC16="",-9999-ROW()*0.0000001,Y16*1000+AC16-ROW()*0.0000001) | AN16: =IF(AND(OR(AD16="Maybe",AD16="Price Review"),AG16<>"Approved",AG16<>"Rejected"),IF(AC16="",0,AC16)-ROW()*0.0000001,-9999-ROW()*0.0000001)
A17: =IF(C17="","","AYN-"&UPPER(LEFT(E17,3))&"-"&TEXT(ROW()-2,"000")) | K17: =IF(I17="","",IF(J17="BDT",I17,IF(J17="USD",I17*USD_BDT,IF(J17="RMB",I17*RMB_BDT,"")))) | O17: =IF(K17="","",K17+IFERROR(L17,0)+(K17*IF(M17="",CUSTOMS_PCT,M17))+IF(N17="",MISC_FEE,N17)) | P17: =IF(O17="","",ROUND(O17*(1+MARKUP_PCT),-1)-1) | Q17: =IF(P17="","",P17-O17) | R17: =IF(OR(P17="",P17=0),"",Q17/P17) | AC17: =IF(COUNT(S17:AB17)<10,"",(S17*W_FEMININE+T17*W_TREND+U17*W_AESTHETIC+V17*W_STYLE+W17*W_LIGHT+X17*W_REELS+Y17*W_GIFT+Z17*W_PRICEFIT+AA17*W_DEMAND+AB17*W_QUALITY)/5*100) | AD17: =IF(P17="","",IF(P17>HARD_REJECT_PRICE,"Reject",IF(P17>MAX_PRICE,"Price Review",IF(AC17="","",IF(AND(AC17>=BUY_THRESHOLD,OR(AB17<=2,U17<=2)),"Maybe",IF(AC17>=BUY_THRESHOLD,"Buy",IF(AC17>=MAYBE_THRESHOLD,"Maybe","Reject"))))))) | AJ17: =IF(AC17="",-9999-ROW()*0.0000001,AC17-ROW()*0.0000001) | AK17: =IF(OR(AC17="",P17="",P17>MAX_PRICE),-9999-ROW()*0.0000001,AC17-ROW()*0.0000001) | AL17: =IF(AC17="",-9999-ROW()*0.0000001,X17*1000+AC17-ROW()*0.0000001) | AM17: =IF(AC17="",-9999-ROW()*0.0000001,Y17*1000+AC17-ROW()*0.0000001) | AN17: =IF(AND(OR(AD17="Maybe",AD17="Price Review"),AG17<>"Approved",AG17<>"Rejected"),IF(AC17="",0,AC17)-ROW()*0.0000001,-9999-ROW()*0.0000001)
A18: =IF(C18="","","AYN-"&UPPER(LEFT(E18,3))&"-"&TEXT(ROW()-2,"000")) | K18: =IF(I18="","",IF(J18="BDT",I18,IF(J18="USD",I18*USD_BDT,IF(J18="RMB",I18*RMB_BDT,"")))) | O18: =IF(K18="","",K18+IFERROR(L18,0)+(K18*IF(M18="",CUSTOMS_PCT,M18))+IF(N18="",MISC_FEE,N18)) | P18: =IF(O18="","",ROUND(O18*(1+MARKUP_PCT),-1)-1) | Q18: =IF(P18="","",P18-O18) | R18: =IF(OR(P18="",P18=0),"",Q18/P18) | AC18: =IF(COUNT(S18:AB18)<10,"",(S18*W_FEMININE+T18*W_TREND+U18*W_AESTHETIC+V18*W_STYLE+W18*W_LIGHT+X18*W_REELS+Y18*W_GIFT+Z18*W_PRICEFIT+AA18*W_DEMAND+AB18*W_QUALITY)/5*100) | AD18: =IF(P18="","",IF(P18>HARD_REJECT_PRICE,"Reject",IF(P18>MAX_PRICE,"Price Review",IF(AC18="","",IF(AND(AC18>=BUY_THRESHOLD,OR(AB18<=2,U18<=2)),"Maybe",IF(AC18>=BUY_THRESHOLD,"Buy",IF(AC18>=MAYBE_THRESHOLD,"Maybe","Reject"))))))) | AJ18: =IF(AC18="",-9999-ROW()*0.0000001,AC18-ROW()*0.0000001) | AK18: =IF(OR(AC18="",P18="",P18>MAX_PRICE),-9999-ROW()*0.0000001,AC18-ROW()*0.0000001) | AL18: =IF(AC18="",-9999-ROW()*0.0000001,X18*1000+AC18-ROW()*0.0000001) | AM18: =IF(AC18="",-9999-ROW()*0.0000001,Y18*1000+AC18-ROW()*0.0000001) | AN18: =IF(AND(OR(AD18="Maybe",AD18="Price Review"),AG18<>"Approved",AG18<>"Rejected"),IF(AC18="",0,AC18)-ROW()*0.0000001,-9999-ROW()*0.0000001)
A19: =IF(C19="","","AYN-"&UPPER(LEFT(E19,3))&"-"&TEXT(ROW()-2,"000")) | K19: =IF(I19="","",IF(J19="BDT",I19,IF(J19="USD",I19*USD_BDT,IF(J19="RMB",I19*RMB_BDT,"")))) | O19: =IF(K19="","",K19+IFERROR(L19,0)+(K19*IF(M19="",CUSTOMS_PCT,M19))+IF(N19="",MISC_FEE,N19)) | P19: =IF(O19="","",ROUND(O19*(1+MARKUP_PCT),-1)-1) | Q19: =IF(P19="","",P19-O19) | R19: =IF(OR(P19="",P19=0),"",Q19/P19) | AC19: =IF(COUNT(S19:AB19)<10,"",(S19*W_FEMININE+T19*W_TREND+U19*W_AESTHETIC+V19*W_STYLE+W19*W_LIGHT+X19*W_REELS+Y19*W_GIFT+Z19*W_PRICEFIT+AA19*W_DEMAND+AB19*W_QUALITY)/5*100) | AD19: =IF(P19="","",IF(P19>HARD_REJECT_PRICE,"Reject",IF(P19>MAX_PRICE,"Price Review",IF(AC19="","",IF(AND(AC19>=BUY_THRESHOLD,OR(AB19<=2,U19<=2)),"Maybe",IF(AC19>=BUY_THRESHOLD,"Buy",IF(AC19>=MAYBE_THRESHOLD,"Maybe","Reject"))))))) | AJ19: =IF(AC19="",-9999-ROW()*0.0000001,AC19-ROW()*0.0000001) | AK19: =IF(OR(AC19="",P19="",P19>MAX_PRICE),-9999-ROW()*0.0000001,AC19-ROW()*0.0000001) | AL19: =IF(AC19="",-9999-ROW()*0.0000001,X19*1000+AC19-ROW()*0.0000001) | AM19: =IF(AC19="",-9999-ROW()*0.0000001,Y19*1000+AC19-ROW()*0.0000001) | AN19: =IF(AND(OR(AD19="Maybe",AD19="Price Review"),AG19<>"Approved",AG19<>"Rejected"),IF(AC19="",0,AC19)-ROW()*0.0000001,-9999-ROW()*0.0000001)
... A42: =IF(C42="","","AYN-"&UPPER(LEFT(E42,3))&"-"&TEXT(ROW()-2,"000")) | K42: =IF(I42="","",IF(J42="BDT",I42,IF(J42="USD",I42*USD_BDT,IF(J42="RMB",I42*RMB_BDT,"")))) | O42: =IF(K42="","",K42+IFERROR(L42,0)+(K42*IF(M42="",CUSTOMS_PCT,M42))+IF(N42="",MISC_FEE,N42)) | P42: =IF(O42="","",ROUND(O42*(1+MARKUP_PCT),-1)-1) | Q42: =IF(P42="","",P42-O42) | R42: =IF(OR(P42="",P42=0),"",Q42/P42) | AC42: =IF(COUNT(S42:AB42)<10,"",(S42*W_FEMININE+T42*W_TREND+U42*W_AESTHETIC+V42*W_STYLE+W42*W_LIGHT+X42*W_REELS+Y42*W_GIFT+Z42*W_PRICEFIT+AA42*W_DEMAND+AB42*W_QUALITY)/5*100) | AD42: =IF(P42="","",IF(P42>HARD_REJECT_PRICE,"Reject",IF(P42>MAX_PRICE,"Price Review",IF(AC42="","",IF(AND(AC42>=BUY_THRESHOLD,OR(AB42<=2,U42<=2)),"Maybe",IF(AC42>=BUY_THRESHOLD,"Buy",IF(AC42>=MAYBE_THRESHOLD,"Maybe","Reject"))))))) | AJ42: =IF(AC42="",-9999-ROW()*0.0000001,AC42-ROW()*0.0000001) | AK42: =IF(OR(AC42="",P42="",P42>MAX_PRICE),-9999-ROW()*0.0000001,AC42-ROW()*0.0000001) | AL42: =IF(AC42="",-9999-ROW()*0.0000001,X42*1000+AC42-ROW()*0.0000001) | AM42: =IF(AC42="",-9999-ROW()*0.0000001,Y42*1000+AC42-ROW()*0.0000001) | AN42: =IF(AND(OR(AD42="Maybe",AD42="Price Review"),AG42<>"Approved",AG42<>"Rejected"),IF(AC42="",0,AC42)-ROW()*0.0000001,-9999-ROW()*0.0000001)

Sheet Dashboard
A1: AAYNA Product Scout Lite — Dashboard
A2: Live view of the Product Tracker tab. Nothing here is editable — everything updates automatically.
A4: Summary
A5: Total products scouted | B5: =COUNTA('Product Tracker'!C3:C42)
A6: Buy | B6: =COUNTIF('Product Tracker'!AD3:AD42,"Buy")
A7: Maybe | B7: =COUNTIF('Product Tracker'!AD3:AD42,"Maybe")
A8: Price Review | B8: =COUNTIF('Product Tracker'!AD3:AD42,"Price Review")
A9: Reject | B9: =COUNTIF('Product Tracker'!AD3:AD42,"Reject")
A12: Top 10 Highest Scoring Products
A13: Rank | B13: Product Name | C13: SKU | D13: Score | E13: Decision | F13: Suggested Price
A14: 1 | B14: =IF(LARGE('Product Tracker'!$AJ$3:$AJ$42,1)>-9000,IFERROR(INDEX('Product Tracker'!$C$3:$C$42,MATCH(LARGE('Product Tracker'!$AJ$3:$AJ$42,1),'Product Tracker'!$AJ$3:$AJ$42,0)),""),"") | C14: =IF(LARGE('Product Tracker'!$AJ$3:$AJ$42,1)>-9000,IFERROR(INDEX('Product Tracker'!$A$3:$A$42,MATCH(LARGE('Product Tracker'!$AJ$3:$AJ$42,1),'Product Tracker'!$AJ$3:$AJ$42,0)),""),"") | D14: =IF(LARGE('Product Tracker'!$AJ$3:$AJ$42,1)>-9000,IFERROR(INDEX('Product Tracker'!$AC$3:$AC$42,MATCH(LARGE('Product Tracker'!$AJ$3:$AJ$42,1),'Product Tracker'!$AJ$3:$AJ$42,0)),""),"") | E14: =IF(LARGE('Product Tracker'!$AJ$3:$AJ$42,1)>-9000,IFERROR(INDEX('Product Tracker'!$AD$3:$AD$42,MATCH(LARGE('Product Tracker'!$AJ$3:$AJ$42,1),'Product Tracker'!$AJ$3:$AJ$42,0)),""),"") | F14: =IF(LARGE('Product Tracker'!$AJ$3:$AJ$42,1)>-9000,IFERROR(INDEX('Product Tracker'!$P$3:$P$42,MATCH(LARGE('Product Tracker'!$AJ$3:$AJ$42,1),'Product Tracker'!$AJ$3:$AJ$42,0)),""),"")
A15: 2 | B15: =IF(LARGE('Product Tracker'!$AJ$3:$AJ$42,2)>-9000,IFERROR(INDEX('Product Tracker'!$C$3:$C$42,MATCH(LARGE('Product Tracker'!$AJ$3:$AJ$42,2),'Product Tracker'!$AJ$3:$AJ$42,0)),""),"") | C15: =IF(LARGE('Product Tracker'!$AJ$3:$AJ$42,2)>-9000,IFERROR(INDEX('Product Tracker'!$A$3:$A$42,MATCH(LARGE('Product Tracker'!$AJ$3:$AJ$42,2),'Product Tracker'!$AJ$3:$AJ$42,0)),""),"") | D15: =IF(LARGE('Product Tracker'!$AJ$3:$AJ$42,2)>-9000,IFERROR(INDEX('Product Tracker'!$AC$3:$AC$42,MATCH(LARGE('Product Tracker'!$AJ$3:$AJ$42,2),'Product Tracker'!$AJ$3:$AJ$42,0)),""),"") | E15: =IF(LARGE('Product Tracker'!$AJ$3:$AJ$42,2)>-9000,IFERROR(INDEX('Product Tracker'!$AD$3:$AD$42,MATCH(LARGE('Product Tracker'!$AJ$3:$AJ$42,2),'Product Tracker'!$AJ$3:$AJ$42,0)),""),"") | F15: =IF(LARGE('Product Tracker'!$AJ$3:$AJ$42,2)>-9000,IFERROR(INDEX('Product Tracker'!$P$3:$P$42,MATCH(LARGE('Product Tracker'!$AJ$3:$AJ$42,2),'Product Tracker'!$AJ$3:$AJ$42,0)),""),"")
A16: 3 | B16: =IF(LARGE('Product Tracker'!$AJ$3:$AJ$42,3)>-9000,IFERROR(INDEX('Product Tracker'!$C$3:$C$42,MATCH(LARGE('Product Tracker'!$AJ$3:$AJ$42,3),'Product Tracker'!$AJ$3:$AJ$42,0)),""),"") | C16: =IF(LARGE('Product Tracker'!$AJ$3:$AJ$42,3)>-9000,IFERROR(INDEX('Product Tracker'!$A$3:$A$42,MATCH(LARGE('Product Tracker'!$AJ$3:$AJ$42,3),'Product Tracker'!$AJ$3:$AJ$42,0)),""),"") | D16: =IF(LARGE('Product Tracker'!$AJ$3:$AJ$42,3)>-9000,IFERROR(INDEX('Product Tracker'!$AC$3:$AC$42,MATCH(LARGE('Product Tracker'!$AJ$3:$AJ$42,3),'Product Tracker'!$AJ$3:$AJ$42,0)),""),"") | E16: =IF(LARGE('Product Tracker'!$AJ$3:$AJ$42,3)>-9000,IFERROR(INDEX('Product Tracker'!$AD$3:$AD$42,MATCH(LARGE('Product Tracker'!$AJ$3:$AJ$42,3),'Product Tracker'!$AJ$3:$AJ$42,0)),""),"") | F16: =IF(LARGE('Product Tracker'!$AJ$3:$AJ$42,3)>-9000,IFERROR(INDEX('Product Tracker'!$P$3:$P$42,MATCH(LARGE('Product Tracker'!$AJ$3:$AJ$42,3),'Product Tracker'!$AJ$3:$AJ$42,0)),""),"")
A17: 4 | B17: =IF(LARGE('Product Tracker'!$AJ$3:$AJ$42,4)>-9000,IFERROR(INDEX('Product Tracker'!$C$3:$C$42,MATCH(LARGE('Product Tracker'!$AJ$3:$AJ$42,4),'Product Tracker'!$AJ$3:$AJ$42,0)),""),"") | C17: =IF(LARGE('Product Tracker'!$AJ$3:$AJ$42,4)>-9000,IFERROR(INDEX('Product Tracker'!$A$3:$A$42,MATCH(LARGE('Product Tracker'!$AJ$3:$AJ$42,4),'Product Tracker'!$AJ$3:$AJ$42,0)),""),"") | D17: =IF(LARGE('Product Tracker'!$AJ$3:$AJ$42,4)>-9000,IFERROR(INDEX('Product Tracker'!$AC$3:$AC$42,MATCH(LARGE('Product Tracker'!$AJ$3:$AJ$42,4),'Product Tracker'!$AJ$3:$AJ$42,0)),""),"") | E17: =IF(LARGE('Product Tracker'!$AJ$3:$AJ$42,4)>-9000,IFERROR(INDEX('Product Tracker'!$AD$3:$AD$42,MATCH(LARGE('Product Tracker'!$AJ$3:$AJ$42,4),'Product Tracker'!$AJ$3:$AJ$42,0)),""),"") | F17: =IF(LARGE('Product Tracker'!$AJ$3:$AJ$42,4)>-9000,IFERROR(INDEX('Product Tracker'!$P$3:$P$42,MATCH(LARGE('Product Tracker'!$AJ$3:$AJ$42,4),'Product Tracker'!$AJ$3:$AJ$42,0)),""),"")
A18: 5 | B18: =IF(LARGE('Product Tracker'!$AJ$3:$AJ$42,5)>-9000,IFERROR(INDEX('Product Tracker'!$C$3:$C$42,MATCH(LARGE('Product Tracker'!$AJ$3:$AJ$42,5),'Product Tracker'!$AJ$3:$AJ$42,0)),""),"") | C18: =IF(LARGE('Product Tracker'!$AJ$3:$AJ$42,5)>-9000,IFERROR(INDEX('Product Tracker'!$A$3:$A$42,MATCH(LARGE('Product Tracker'!$AJ$3:$AJ$42,5),'Product Tracker'!$AJ$3:$AJ$42,0)),""),"") | D18: =IF(LARGE('Product Tracker'!$AJ$3:$AJ$42,5)>-9000,IFERROR(INDEX('Product Tracker'!$AC$3:$AC$42,MATCH(LARGE('Product Tracker'!$AJ$3:$AJ$42,5),'Product Tracker'!$AJ$3:$AJ$42,0)),""),"") | E18: =IF(LARGE('Product Tracker'!$AJ$3:$AJ$42,5)>-9000,IFERROR(INDEX('Product Tracker'!$AD$3:$AD$42,MATCH(LARGE('Product Tracker'!$AJ$3:$AJ$42,5),'Product Tracker'!$AJ$3:$AJ$42,0)),""),"") | F18: =IF(LARGE('Product Tracker'!$AJ$3:$AJ$42,5)>-9000,IFERROR(INDEX('Product Tracker'!$P$3:$P$42,MATCH(LARGE('Product Tracker'!$AJ$3:$AJ$42,5),'Product Tracker'!$AJ$3:$AJ$42,0)),""),"")
A19: 6 | B19: =IF(LARGE('Product Tracker'!$AJ$3:$AJ$42,6)>-9000,IFERROR(INDEX('Product Tracker'!$C$3:$C$42,MATCH(LARGE('Product Tracker'!$AJ$3:$AJ$42,6),'Product Tracker'!$AJ$3:$AJ$42,0)),""),"") | C19: =IF(LARGE('Product Tracker'!$AJ$3:$AJ$42,6)>-9000,IFERROR(INDEX('Product Tracker'!$A$3:$A$42,MATCH(LARGE('Product Tracker'!$AJ$3:$AJ$42,6),'Product Tracker'!$AJ$3:$AJ$42,0)),""),"") | D19: =IF(LARGE('Product Tracker'!$AJ$3:$AJ$42,6)>-9000,IFERROR(INDEX('Product Tracker'!$AC$3:$AC$42,MATCH(LARGE('Product Tracker'!$AJ$3:$AJ$42,6),'Product Tracker'!$AJ$3:$AJ$42,0)),""),"") | E19: =IF(LARGE('Product Tracker'!$AJ$3:$AJ$42,6)>-9000,IFERROR(INDEX('Product Tracker'!$AD$3:$AD$42,MATCH(LARGE('Product Tracker'!$AJ$3:$AJ$42,6),'Product Tracker'!$AJ$3:$AJ$42,0)),""),"") | F19: =IF(LARGE('Product Tracker'!$AJ$3:$AJ$42,6)>-9000,IFERROR(INDEX('Product Tracker'!$P$3:$P$42,MATCH(LARGE('Product Tracker'!$AJ$3:$AJ$42,6),'Product Tracker'!$AJ$3:$AJ$42,0)),""),"")
A20: 7 | B20: =IF(LARGE('Product Tracker'!$AJ$3:$AJ$42,7)>-9000,IFERROR(INDEX('Product Tracker'!$C$3:$C$42,MATCH(LARGE('Product Tracker'!$AJ$3:$AJ$42,7),'Product Tracker'!$AJ$3:$AJ$42,0)),""),"") | C20: =IF(LARGE('Product Tracker'!$AJ$3:$AJ$42,7)>-9000,IFERROR(INDEX('Product Tracker'!$A$3:$A$42,MATCH(LARGE('Product Tracker'!$AJ$3:$AJ$42,7),'Product Tracker'!$AJ$3:$AJ$42,0)),""),"") | D20: =IF(LARGE('Product Tracker'!$AJ$3:$AJ$42,7)>-9000,IFERROR(INDEX('Product Tracker'!$AC$3:$AC$42,MATCH(LARGE('Product Tracker'!$AJ$3:$AJ$42,7),'Product Tracker'!$AJ$3:$AJ$42,0)),""),"") | E20: =IF(LARGE('Product Tracker'!$AJ$3:$AJ$42,7)>-9000,IFERROR(INDEX('Product Tracker'!$AD$3:$AD$42,MATCH(LARGE('Product Tracker'!$AJ$3:$AJ$42,7),'Product Tracker'!$AJ$3:$AJ$42,0)),""),"") | F20: =IF(LARGE('Product Tracker'!$AJ$3:$AJ$42,7)>-9000,IFERROR(INDEX('Product Tracker'!$P$3:$P$42,MATCH(LARGE('Product Tracker'!$AJ$3:$AJ$42,7),'Product Tracker'!$AJ$3:$AJ$42,0)),""),"")
A21: 8 | B21: =IF(LARGE('Product Tracker'!$AJ$3:$AJ$42,8)>-9000,IFERROR(INDEX('Product Tracker'!$C$3:$C$42,MATCH(LARGE('Product Tracker'!$AJ$3:$AJ$42,8),'Product Tracker'!$AJ$3:$AJ$42,0)),""),"") | C21: =IF(LARGE('Product Tracker'!$AJ$3:$AJ$42,8)>-9000,IFERROR(INDEX('Product Tracker'!$A$3:$A$42,MATCH(LARGE('Product Tracker'!$AJ$3:$AJ$42,8),'Product Tracker'!$AJ$3:$AJ$42,0)),""),"") | D21: =IF(LARGE('Product Tracker'!$AJ$3:$AJ$42,8)>-9000,IFERROR(INDEX('Product Tracker'!$AC$3:$AC$42,MATCH(LARGE('Product Tracker'!$AJ$3:$AJ$42,8),'Product Tracker'!$AJ$3:$AJ$42,0)),""),"") | E21: =IF(LARGE('Product Tracker'!$AJ$3:$AJ$42,8)>-9000,IFERROR(INDEX('Product Tracker'!$AD$3:$AD$42,MATCH(LARGE('Product Tracker'!$AJ$3:$AJ$42,8),'Product Tracker'!$AJ$3:$AJ$42,0)),""),"") | F21: =IF(LARGE('Product Tracker'!$AJ$3:$AJ$42,8)>-9000,IFERROR(INDEX('Product Tracker'!$P$3:$P$42,MATCH(LARGE('Product Tracker'!$AJ$3:$AJ$42,8),'Product Tracker'!$AJ$3:$AJ$42,0)),""),"")
A22: 9 | B22: =IF(LARGE('Product Tracker'!$AJ$3:$AJ$42,9)>-9000,IFERROR(INDEX('Product Tracker'!$C$3:$C$42,MATCH(LARGE('Product Tracker'!$AJ$3:$AJ$42,9),'Product Tracker'!$AJ$3:$AJ$42,0)),""),"") | C22: =IF(LARGE('Product Tracker'!$AJ$3:$AJ$42,9)>-9000,IFERROR(INDEX('Product Tracker'!$A$3:$A$42,MATCH(LARGE('Product Tracker'!$AJ$3:$AJ$42,9),'Product Tracker'!$AJ$3:$AJ$42,0)),""),"") | D22: =IF(LARGE('Product Tracker'!$AJ$3:$AJ$42,9)>-9000,IFERROR(INDEX('Product Tracker'!$AC$3:$AC$42,MATCH(LARGE('Product Tracker'!$AJ$3:$AJ$42,9),'Product Tracker'!$AJ$3:$AJ$42,0)),""),"") | E22: =IF(LARGE('Product Tracker'!$AJ$3:$AJ$42,9)>-9000,IFERROR(INDEX('Product Tracker'!$AD$3:$AD$42,MATCH(LARGE('Product Tracker'!$AJ$3:$AJ$42,9),'Product Tracker'!$AJ$3:$AJ$42,0)),""),"") | F22: =IF(LARGE('Product Tracker'!$AJ$3:$AJ$42,9)>-9000,IFERROR(INDEX('Product Tracker'!$P$3:$P$42,MATCH(LARGE('Product Tracker'!$AJ$3:$AJ$42,9),'Product Tracker'!$AJ$3:$AJ$42,0)),""),"")
A23: 10 | B23: =IF(LARGE('Product Tracker'!$AJ$3:$AJ$42,10)>-9000,IFERROR(INDEX('Product Tracker'!$C$3:$C$42,MATCH(LARGE('Product Tracker'!$AJ$3:$AJ$42,10),'Product Tracker'!$AJ$3:$AJ$42,0)),""),"") | C23: =IF(LARGE('Product Tracker'!$AJ$3:$AJ$42,10)>-9000,IFERROR(INDEX('Product Tracker'!$A$3:$A$42,MATCH(LARGE('Product Tracker'!$AJ$3:$AJ$42,10),'Product Tracker'!$AJ$3:$AJ$42,0)),""),"") | D23: =IF(LARGE('Product Tracker'!$AJ$3:$AJ$42,10)>-9000,IFERROR(INDEX('Product Tracker'!$AC$3:$AC$42,MATCH(LARGE('Product Tracker'!$AJ$3:$AJ$42,10),'Product Tracker'!$AJ$3:$AJ$42,0)),""),"") | E23: =IF(LARGE('Product Tracker'!$AJ$3:$AJ$42,10)>-9000,IFERROR(INDEX('Product Tracker'!$AD$3:$AD$42,MATCH(LARGE('Product Tracker'!$AJ$3:$AJ$42,10),'Product Tracker'!$AJ$3:$AJ$42,0)),""),"") | F23: =IF(LARGE('Product Tracker'!$AJ$3:$AJ$42,10)>-9000,IFERROR(INDEX('Product Tracker'!$P$3:$P$42,MATCH(LARGE('Product Tracker'!$AJ$3:$AJ$42,10),'Product Tracker'!$AJ$3:$AJ$42,0)),""),"")
A24: Best Products Under BDT 700
A25: Rank | B25: Product Name | C25: SKU | D25: Score | E25: Decision | F25: Suggested Price
A26: 1 | B26: =IF(LARGE('Product Tracker'!$AK$3:$AK$42,1)>-9000,IFERROR(INDEX('Product Tracker'!$C$3:$C$42,MATCH(LARGE('Product Tracker'!$AK$3:$AK$42,1),'Product Tracker'!$AK$3:$AK$42,0)),""),"") | C26: =IF(LARGE('Product Tracker'!$AK$3:$AK$42,1)>-9000,IFERROR(INDEX('Product Tracker'!$A$3:$A$42,MATCH(LARGE('Product Tracker'!$AK$3:$AK$42,1),'Product Tracker'!$AK$3:$AK$42,0)),""),"") | D26: =IF(LARGE('Product Tracker'!$AK$3:$AK$42,1)>-9000,IFERROR(INDEX('Product Tracker'!$AC$3:$AC$42,MATCH(LARGE('Product Tracker'!$AK$3:$AK$42,1),'Product Tracker'!$AK$3:$AK$42,0)),""),"") | E26: =IF(LARGE('Product Tracker'!$AK$3:$AK$42,1)>-9000,IFERROR(INDEX('Product Tracker'!$AD$3:$AD$42,MATCH(LARGE('Product Tracker'!$AK$3:$AK$42,1),'Product Tracker'!$AK$3:$AK$42,0)),""),"") | F26: =IF(LARGE('Product Tracker'!$AK$3:$AK$42,1)>-9000,IFERROR(INDEX('Product Tracker'!$P$3:$P$42,MATCH(LARGE('Product Tracker'!$AK$3:$AK$42,1),'Product Tracker'!$AK$3:$AK$42,0)),""),"")
A27: 2 | B27: =IF(LARGE('Product Tracker'!$AK$3:$AK$42,2)>-9000,IFERROR(INDEX('Product Tracker'!$C$3:$C$42,MATCH(LARGE('Product Tracker'!$AK$3:$AK$42,2),'Product Tracker'!$AK$3:$AK$42,0)),""),"") | C27: =IF(LARGE('Product Tracker'!$AK$3:$AK$42,2)>-9000,IFERROR(INDEX('Product Tracker'!$A$3:$A$42,MATCH(LARGE('Product Tracker'!$AK$3:$AK$42,2),'Product Tracker'!$AK$3:$AK$42,0)),""),"") | D27: =IF(LARGE('Product Tracker'!$AK$3:$AK$42,2)>-9000,IFERROR(INDEX('Product Tracker'!$AC$3:$AC$42,MATCH(LARGE('Product Tracker'!$AK$3:$AK$42,2),'Product Tracker'!$AK$3:$AK$42,0)),""),"") | E27: =IF(LARGE('Product Tracker'!$AK$3:$AK$42,2)>-9000,IFERROR(INDEX('Product Tracker'!$AD$3:$AD$42,MATCH(LARGE('Product Tracker'!$AK$3:$AK$42,2),'Product Tracker'!$AK$3:$AK$42,0)),""),"") | F27: =IF(LARGE('Product Tracker'!$AK$3:$AK$42,2)>-9000,IFERROR(INDEX('Product Tracker'!$P$3:$P$42,MATCH(LARGE('Product Tracker'!$AK$3:$AK$42,2),'Product Tracker'!$AK$3:$AK$42,0)),""),"")
A28: 3 | B28: =IF(LARGE('Product Tracker'!$AK$3:$AK$42,3)>-9000,IFERROR(INDEX('Product Tracker'!$C$3:$C$42,MATCH(LARGE('Product Tracker'!$AK$3:$AK$42,3),'Product Tracker'!$AK$3:$AK$42,0)),""),"") | C28: =IF(LARGE('Product Tracker'!$AK$3:$AK$42,3)>-9000,IFERROR(INDEX('Product Tracker'!$A$3:$A$42,MATCH(LARGE('Product Tracker'!$AK$3:$AK$42,3),'Product Tracker'!$AK$3:$AK$42,0)),""),"") | D28: =IF(LARGE('Product Tracker'!$AK$3:$AK$42,3)>-9000,IFERROR(INDEX('Product Tracker'!$AC$3:$AC$42,MATCH(LARGE('Product Tracker'!$AK$3:$AK$42,3),'Product Tracker'!$AK$3:$AK$42,0)),""),"") | E28: =IF(LARGE('Product Tracker'!$AK$3:$AK$42,3)>-9000,IFERROR(INDEX('Product Tracker'!$AD$3:$AD$42,MATCH(LARGE('Product Tracker'!$AK$3:$AK$42,3),'Product Tracker'!$AK$3:$AK$42,0)),""),"") | F28: =IF(LARGE('Product Tracker'!$AK$3:$AK$42,3)>-9000,IFERROR(INDEX('Product Tracker'!$P$3:$P$42,MATCH(LARGE('Product Tracker'!$AK$3:$AK$42,3),'Product Tracker'!$AK$3:$AK$42,0)),""),"")
A29: 4 | B29: =IF(LARGE('Product Tracker'!$AK$3:$AK$42,4)>-9000,IFERROR(INDEX('Product Tracker'!$C$3:$C$42,MATCH(LARGE('Product Tracker'!$AK$3:$AK$42,4),'Product Tracker'!$AK$3:$AK$42,0)),""),"") | C29: =IF(LARGE('Product Tracker'!$AK$3:$AK$42,4)>-9000,IFERROR(INDEX('Product Tracker'!$A$3:$A$42,MATCH(LARGE('Product Tracker'!$AK$3:$AK$42,4),'Product Tracker'!$AK$3:$AK$42,0)),""),"") | D29: =IF(LARGE('Product Tracker'!$AK$3:$AK$42,4)>-9000,IFERROR(INDEX('Product Tracker'!$AC$3:$AC$42,MATCH(LARGE('Product Tracker'!$AK$3:$AK$42,4),'Product Tracker'!$AK$3:$AK$42,0)),""),"") | E29: =IF(LARGE('Product Tracker'!$AK$3:$AK$42,4)>-9000,IFERROR(INDEX('Product Tracker'!$AD$3:$AD$42,MATCH(LARGE('Product Tracker'!$AK$3:$AK$42,4),'Product Tracker'!$AK$3:$AK$42,0)),""),"") | F29: =IF(LARGE('Product Tracker'!$AK$3:$AK$42,4)>-9000,IFERROR(INDEX('Product Tracker'!$P$3:$P$42,MATCH(LARGE('Product Tracker'!$AK$3:$AK$42,4),'Product Tracker'!$AK$3:$AK$42,0)),""),"")
A30: 5 | B30: =IF(LARGE('Product Tracker'!$AK$3:$AK$42,5)>-9000,IFERROR(INDEX('Product Tracker'!$C$3:$C$42,MATCH(LARGE('Product Tracker'!$AK$3:$AK$42,5),'Product Tracker'!$AK$3:$AK$42,0)),""),"") | C30: =IF(LARGE('Product Tracker'!$AK$3:$AK$42,5)>-9000,IFERROR(INDEX('Product Tracker'!$A$3:$A$42,MATCH(LARGE('Product Tracker'!$AK$3:$AK$42,5),'Product Tracker'!$AK$3:$AK$42,0)),""),"") | D30: =IF(LARGE('Product Tracker'!$AK$3:$AK$42,5)>-9000,IFERROR(INDEX('Product Tracker'!$AC$3:$AC$42,MATCH(LARGE('Product Tracker'!$AK$3:$AK$42,5),'Product Tracker'!$AK$3:$AK$42,0)),""),"") | E30: =IF(LARGE('Product Tracker'!$AK$3:$AK$42,5)>-9000,IFERROR(INDEX('Product Tracker'!$AD$3:$AD$42,MATCH(LARGE('Product Tracker'!$AK$3:$AK$42,5),'Product Tracker'!$AK$3:$AK$42,0)),""),"") | F30: =IF(LARGE('Product Tracker'!$AK$3:$AK$42,5)>-9000,IFERROR(INDEX('Product Tracker'!$P$3:$P$42,MATCH(LARGE('Product Tracker'!$AK$3:$AK$42,5),'Product Tracker'!$AK$3:$AK$42,0)),""),"")
A31: Best Products for Reels/Photos
A32: Rank | B32: Product Name | C32: SKU | D32: Score | E32: Decision | F32: Suggested Price
A33: 1 | B33: =IF(LARGE('Product Tracker'!$AL$3:$AL$42,1)>-9000,IFERROR(INDEX('Product Tracker'!$C$3:$C$42,MATCH(LARGE('Product Tracker'!$AL$3:$AL$42,1),'Product Tracker'!$AL$3:$AL$42,0)),""),"") | C33: =IF(LARGE('Product Tracker'!$AL$3:$AL$42,1)>-9000,IFERROR(INDEX('Product Tracker'!$A$3:$A$42,MATCH(LARGE('Product Tracker'!$AL$3:$AL$42,1),'Product Tracker'!$AL$3:$AL$42,0)),""),"") | D33: =IF(LARGE('Product Tracker'!$AL$3:$AL$42,1)>-9000,IFERROR(INDEX('Product Tracker'!$AC$3:$AC$42,MATCH(LARGE('Product Tracker'!$AL$3:$AL$42,1),'Product Tracker'!$AL$3:$AL$42,0)),""),"") | E33: =IF(LARGE('Product Tracker'!$AL$3:$AL$42,1)>-9000,IFERROR(INDEX('Product Tracker'!$AD$3:$AD$42,MATCH(LARGE('Product Tracker'!$AL$3:$AL$42,1),'Product Tracker'!$AL$3:$AL$42,0)),""),"") | F33: =IF(LARGE('Product Tracker'!$AL$3:$AL$42,1)>-9000,IFERROR(INDEX('Product Tracker'!$P$3:$P$42,MATCH(LARGE('Product Tracker'!$AL$3:$AL$42,1),'Product Tracker'!$AL$3:$AL$42,0)),""),"")
A34: 2 | B34: =IF(LARGE('Product Tracker'!$AL$3:$AL$42,2)>-9000,IFERROR(INDEX('Product Tracker'!$C$3:$C$42,MATCH(LARGE('Product Tracker'!$AL$3:$AL$42,2),'Product Tracker'!$AL$3:$AL$42,0)),""),"") | C34: =IF(LARGE('Product Tracker'!$AL$3:$AL$42,2)>-9000,IFERROR(INDEX('Product Tracker'!$A$3:$A$42,MATCH(LARGE('Product Tracker'!$AL$3:$AL$42,2),'Product Tracker'!$AL$3:$AL$42,0)),""),"") | D34: =IF(LARGE('Product Tracker'!$AL$3:$AL$42,2)>-9000,IFERROR(INDEX('Product Tracker'!$AC$3:$AC$42,MATCH(LARGE('Product Tracker'!$AL$3:$AL$42,2),'Product Tracker'!$AL$3:$AL$42,0)),""),"") | E34: =IF(LARGE('Product Tracker'!$AL$3:$AL$42,2)>-9000,IFERROR(INDEX('Product Tracker'!$AD$3:$AD$42,MATCH(LARGE('Product Tracker'!$AL$3:$AL$42,2),'Product Tracker'!$AL$3:$AL$42,0)),""),"") | F34: =IF(LARGE('Product Tracker'!$AL$3:$AL$42,2)>-9000,IFERROR(INDEX('Product Tracker'!$P$3:$P$42,MATCH(LARGE('Product Tracker'!$AL$3:$AL$42,2),'Product Tracker'!$AL$3:$AL$42,0)),""),"")
A35: 3 | B35: =IF(LARGE('Product Tracker'!$AL$3:$AL$42,3)>-9000,IFERROR(INDEX('Product Tracker'!$C$3:$C$42,MATCH(LARGE('Product Tracker'!$AL$3:$AL$42,3),'Product Tracker'!$AL$3:$AL$42,0)),""),"") | C35: =IF(LARGE('Product Tracker'!$AL$3:$AL$42,3)>-9000,IFERROR(INDEX('Product Tracker'!$A$3:$A$42,MATCH(LARGE('Product Tracker'!$AL$3:$AL$42,3),'Product Tracker'!$AL$3:$AL$42,0)),""),"") | D35: =IF(LARGE('Product Tracker'!$AL$3:$AL$42,3)>-9000,IFERROR(INDEX('Product Tracker'!$AC$3:$AC$42,MATCH(LARGE('Product Tracker'!$AL$3:$AL$42,3),'Product Tracker'!$AL$3:$AL$42,0)),""),"") | E35: =IF(LARGE('Product Tracker'!$AL$3:$AL$42,3)>-9000,IFERROR(INDEX('Product Tracker'!$AD$3:$AD$42,MATCH(LARGE('Product Tracker'!$AL$3:$AL$42,3),'Product Tracker'!$AL$3:$AL$42,0)),""),"") | F35: =IF(LARGE('Product Tracker'!$AL$3:$AL$42,3)>-9000,IFERROR(INDEX('Product Tracker'!$P$3:$P$42,MATCH(LARGE('Product Tracker'!$AL$3:$AL$42,3),'Product Tracker'!$AL$3:$AL$42,0)),""),"")
A36: 4 | B36: =IF(LARGE('Product Tracker'!$AL$3:$AL$42,4)>-9000,IFERROR(INDEX('Product Tracker'!$C$3:$C$42,MATCH(LARGE('Product Tracker'!$AL$3:$AL$42,4),'Product Tracker'!$AL$3:$AL$42,0)),""),"") | C36: =IF(LARGE('Product Tracker'!$AL$3:$AL$42,4)>-9000,IFERROR(INDEX('Product Tracker'!$A$3:$A$42,MATCH(LARGE('Product Tracker'!$AL$3:$AL$42,4),'Product Tracker'!$AL$3:$AL$42,0)),""),"") | D36: =IF(LARGE('Product Tracker'!$AL$3:$AL$42,4)>-9000,IFERROR(INDEX('Product Tracker'!$AC$3:$AC$42,MATCH(LARGE('Product Tracker'!$AL$3:$AL$42,4),'Product Tracker'!$AL$3:$AL$42,0)),""),"") | E36: =IF(LARGE('Product Tracker'!$AL$3:$AL$42,4)>-9000,IFERROR(INDEX('Product Tracker'!$AD$3:$AD$42,MATCH(LARGE('Product Tracker'!$AL$3:$AL$42,4),'Product Tracker'!$AL$3:$AL$42,0)),""),"") | F36: =IF(LARGE('Product Tracker'!$AL$3:$AL$42,4)>-9000,IFERROR(INDEX('Product Tracker'!$P$3:$P$42,MATCH(LARGE('Product Tracker'!$AL$3:$AL$42,4),'Product Tracker'!$AL$3:$AL$42,0)),""),"")
A37: 5 | B37: =IF(LARGE('Product Tracker'!$AL$3:$AL$42,5)>-9000,IFERROR(INDEX('Product Tracker'!$C$3:$C$42,MATCH(LARGE('Product Tracker'!$AL$3:$AL$42,5),'Product Tracker'!$AL$3:$AL$42,0)),""),"") | C37: =IF(LARGE('Product Tracker'!$AL$3:$AL$42,5)>-9000,IFERROR(INDEX('Product Tracker'!$A$3:$A$42,MATCH(LARGE('Product Tracker'!$AL$3:$AL$42,5),'Product Tracker'!$AL$3:$AL$42,0)),""),"") | D37: =IF(LARGE('Product Tracker'!$AL$3:$AL$42,5)>-9000,IFERROR(INDEX('Product Tracker'!$AC$3:$AC$42,MATCH(LARGE('Product Tracker'!$AL$3:$AL$42,5),'Product Tracker'!$AL$3:$AL$42,0)),""),"") | E37: =IF(LARGE('Product Tracker'!$AL$3:$AL$42,5)>-9000,IFERROR(INDEX('Product Tracker'!$AD$3:$AD$42,MATCH(LARGE('Product Tracker'!$AL$3:$AL$42,5),'Product Tracker'!$AL$3:$AL$42,0)),""),"") | F37: =IF(LARGE('Product Tracker'!$AL$3:$AL$42,5)>-9000,IFERROR(INDEX('Product Tracker'!$P$3:$P$42,MATCH(LARGE('Product Tracker'!$AL$3:$AL$42,5),'Product Tracker'!$AL$3:$AL$42,0)),""),"")
A38: Best Giftable Products
A39: Rank | B39: Product Name | C39: SKU | D39: Score | E39: Decision | F39: Suggested Price
A40: 1 | B40: =IF(LARGE('Product Tracker'!$AM$3:$AM$42,1)>-9000,IFERROR(INDEX('Product Tracker'!$C$3:$C$42,MATCH(LARGE('Product Tracker'!$AM$3:$AM$42,1),'Product Tracker'!$AM$3:$AM$42,0)),""),"") | C40: =IF(LARGE('Product Tracker'!$AM$3:$AM$42,1)>-9000,IFERROR(INDEX('Product Tracker'!$A$3:$A$42,MATCH(LARGE('Product Tracker'!$AM$3:$AM$42,1),'Product Tracker'!$AM$3:$AM$42,0)),""),"") | D40: =IF(LARGE('Product Tracker'!$AM$3:$AM$42,1)>-9000,IFERROR(INDEX('Product Tracker'!$AC$3:$AC$42,MATCH(LARGE('Product Tracker'!$AM$3:$AM$42,1),'Product Tracker'!$AM$3:$AM$42,0)),""),"") | E40: =IF(LARGE('Product Tracker'!$AM$3:$AM$42,1)>-9000,IFERROR(INDEX('Product Tracker'!$AD$3:$AD$42,MATCH(LARGE('Product Tracker'!$AM$3:$AM$42,1),'Product Tracker'!$AM$3:$AM$42,0)),""),"") | F40: =IF(LARGE('Product Tracker'!$AM$3:$AM$42,1)>-9000,IFERROR(INDEX('Product Tracker'!$P$3:$P$42,MATCH(LARGE('Product Tracker'!$AM$3:$AM$42,1),'Product Tracker'!$AM$3:$AM$42,0)),""),"")
A41: 2 | B41: =IF(LARGE('Product Tracker'!$AM$3:$AM$42,2)>-9000,IFERROR(INDEX('Product Tracker'!$C$3:$C$42,MATCH(LARGE('Product Tracker'!$AM$3:$AM$42,2),'Product Tracker'!$AM$3:$AM$42,0)),""),"") | C41: =IF(LARGE('Product Tracker'!$AM$3:$AM$42,2)>-9000,IFERROR(INDEX('Product Tracker'!$A$3:$A$42,MATCH(LARGE('Product Tracker'!$AM$3:$AM$42,2),'Product Tracker'!$AM$3:$AM$42,0)),""),"") | D41: =IF(LARGE('Product Tracker'!$AM$3:$AM$42,2)>-9000,IFERROR(INDEX('Product Tracker'!$AC$3:$AC$42,MATCH(LARGE('Product Tracker'!$AM$3:$AM$42,2),'Product Tracker'!$AM$3:$AM$42,0)),""),"") | E41: =IF(LARGE('Product Tracker'!$AM$3:$AM$42,2)>-9000,IFERROR(INDEX('Product Tracker'!$AD$3:$AD$42,MATCH(LARGE('Product Tracker'!$AM$3:$AM$42,2),'Product Tracker'!$AM$3:$AM$42,0)),""),"") | F41: =IF(LARGE('Product Tracker'!$AM$3:$AM$42,2)>-9000,IFERROR(INDEX('Product Tracker'!$P$3:$P$42,MATCH(LARGE('Product Tracker'!$AM$3:$AM$42,2),'Product Tracker'!$AM$3:$AM$42,0)),""),"")
A42: 3 | B42: =IF(LARGE('Product Tracker'!$AM$3:$AM$42,3)>-9000,IFERROR(INDEX('Product Tracker'!$C$3:$C$42,MATCH(LARGE('Product Tracker'!$AM$3:$AM$42,3),'Product Tracker'!$AM$3:$AM$42,0)),""),"") | C42: =IF(LARGE('Product Tracker'!$AM$3:$AM$42,3)>-9000,IFERROR(INDEX('Product Tracker'!$A$3:$A$42,MATCH(LARGE('Product Tracker'!$AM$3:$AM$42,3),'Product Tracker'!$AM$3:$AM$42,0)),""),"") | D42: =IF(LARGE('Product Tracker'!$AM$3:$AM$42,3)>-9000,IFERROR(INDEX('Product Tracker'!$AC$3:$AC$42,MATCH(LARGE('Product Tracker'!$AM$3:$AM$42,3),'Product Tracker'!$AM$3:$AM$42,0)),""),"") | E42: =IF(LARGE('Product Tracker'!$AM$3:$AM$42,3)>-9000,IFERROR(INDEX('Product Tracker'!$AD$3:$AD$42,MATCH(LARGE('Product Tracker'!$AM$3:$AM$42,3),'Product Tracker'!$AM$3:$AM$42,0)),""),"") | F42: =IF(LARGE('Product Tracker'!$AM$3:$AM$42,3)>-9000,IFERROR(INDEX('Product Tracker'!$P$3:$P$42,MATCH(LARGE('Product Tracker'!$AM$3:$AM$42,3),'Product Tracker'!$AM$3:$AM$42,0)),""),"")
A43: 4 | B43: =IF(LARGE('Product Tracker'!$AM$3:$AM$42,4)>-9000,IFERROR(INDEX('Product Tracker'!$C$3:$C$42,MATCH(LARGE('Product Tracker'!$AM$3:$AM$42,4),'Product Tracker'!$AM$3:$AM$42,0)),""),"") | C43: =IF(LARGE('Product Tracker'!$AM$3:$AM$42,4)>-9000,IFERROR(INDEX('Product Tracker'!$A$3:$A$42,MATCH(LARGE('Product Tracker'!$AM$3:$AM$42,4),'Product Tracker'!$AM$3:$AM$42,0)),""),"") | D43: =IF(LARGE('Product Tracker'!$AM$3:$AM$42,4)>-9000,IFERROR(INDEX('Product Tracker'!$AC$3:$AC$42,MATCH(LARGE('Product Tracker'!$AM$3:$AM$42,4),'Product Tracker'!$AM$3:$AM$42,0)),""),"") | E43: =IF(LARGE('Product Tracker'!$AM$3:$AM$42,4)>-9000,IFERROR(INDEX('Product Tracker'!$AD$3:$AD$42,MATCH(LARGE('Product Tracker'!$AM$3:$AM$42,4),'Product Tracker'!$AM$3:$AM$42,0)),""),"") | F43: =IF(LARGE('Product Tracker'!$AM$3:$AM$42,4)>-9000,IFERROR(INDEX('Product Tracker'!$P$3:$P$42,MATCH(LARGE('Product Tracker'!$AM$3:$AM$42,4),'Product Tracker'!$AM$3:$AM$42,0)),""),"")
...

Sheet Claude Scoring Prompt
A1: AAYNA Product Scout Lite — Claude Scoring Prompt
A2: Copy everything in the box below into Claude (or another AI assistant), paste in the product photo/link/description where indicated, then copy Claude's reply back into the matching score columns on the Product Tracker tab.
A4: You are helping AAYNA, a Bangladesh-based women's accessories brand, evaluate a sourcing candidate product. AAYNA's brand identity: feminine, trendy, affordable, clean and modern, with a warm, social-media-friendly feel. Visual aesthetic: dusty rose, cream white, antique gold, and espresso charcoal. Most products sell under BDT 700. Here is the product: [paste product name, description, photos/link, and supplier price here] Score this product from 1 (worst) to 5 (best) on each of these 10 criteria, with a one-line reason for each score: 1. Feminine Score - how feminine/delicate does it look? 2. Trend Score - how on-trend is it right now (TikTok/Instagram/competitors)? 3. AAYNA Aesthetic Fit Score - how well does it match our dusty rose / cream / antique gold look? 4. Easy to Style Score - how easily can a customer style this with everyday outfits? 5. Lightweight Score - how light/comfortable is it to wear or carry? 6. Reels/Photo Potential Score - how good would this look in a Reel, photo, or unboxing video? 7. Giftability Score - how good is this as a gift? 8. Price Fit Score - how comfortably can we sell this under BDT 700 and still profit? 9. Demand Score - how likely is our target customer to actually want and buy this? 10. Quality/Risk Score - how low is the risk of poor quality, damage in transit, or returns? Then give: - A Recommended Decision: Buy, Maybe, Price Review, or Reject - A one-sentence Reason for that decision - A short Content/Reel Idea for how we'd promote this product Format your answer exactly like this so it's easy to paste into the sheet: Feminine: _ - reason Trend: _ - reason Aesthetic Fit: _ - reason Easy to Style: _ - reason Lightweight: _ - reason Reels/Photo: _ - reason Giftability: _ - reason Price Fit: _ - reason Demand: _ - reason Quality/Risk: _ - reason Recommended Decision: _ Reason: _ Content/Reel Idea: _
A6: Tip: if you ever change the 10 scoring criteria, their order, or the price ceiling in the Settings tab, update this prompt to match so Claude's answers keep lining up with the Product Tracker columns.

Sheet Settings
A1: AAYNA Product Scout Lite — Settings
A2: Tune these numbers once. Every formula in the Product Tracker tab reads from here.
A4: Setting | B4: Value | C4: Notes
A5: USD to BDT exchange rate | B5: 122 | C5: Update when BDT/USD rate changes
A6: RMB (CNY) to BDT exchange rate | B6: 17 | C6: Update when BDT/CNY rate changes
A7: Default customs/duty % | B7: 0.07 | C7: As decimal, e.g. 0.07 = 7%
A8: Default misc fee per unit (BDT) | B8: 15 | C8: Packaging, handling, platform fees per piece
A9: Default markup % over landed cost | B9: 1 | C9: 1.0 = 100% markup (sell at 2x landed cost)
A10: Target max selling price (BDT) | B10: 700 | C10: AAYNA's 'mostly under' price ceiling
A11: Hard reject price ceiling (BDT) | B11: 1000 | C11: Above the target price but at/under this = 'Price Review' (negotiable). Above this = automatic 'Reject'.
A12: Weight: Feminine Score | B12: 0.1 | C12: All 10 weights below must add up to 1.00
A13: Weight: Trend Score | B13: 0.1
A14: Weight: AAYNA Aesthetic Fit Score | B14: 0.15
A15: Weight: Easy to Style Score | B15: 0.08
A16: Weight: Lightweight Score | B16: 0.07
A17: Weight: Reels/Photo Potential Score | B17: 0.1
A18: Weight: Giftability Score | B18: 0.08
A19: Weight: Price Fit Score | B19: 0.12
A20: Weight: Demand Score | B20: 0.12
A21: Weight: Quality/Risk Score | B21: 0.08
A22: Buy threshold (score >=) | B22: 75 | C22: Total Product Score is out of 100
A23: Maybe threshold (score >=) | B23: 50 | C23: Below this = Reject

Sheet Dropdown Lists
A1: Source Platform | B1: Category | C1: Source Currency | D1: Decision | E1: Approval Status | F1: Score (1-5)
A2: SkyBuyBD | B2: Earrings | C2: BDT | D2: Buy | E2: Pending | F2: 1
A3: AliExpress | B3: Necklace | C3: USD | D3: Maybe | E3: Approved | F3: 2
A4: Yiwugo | B4: Bracelet | C4: RMB | D4: Price Review | E4: Rejected | F4: 3
A5: 1688 | B5: Ring | D5: Reject | E5: On Hold | F5: 4
A6: Local Wholesale | B6: Hair Accessory | F6: 5
A7: Other | B7: Bag
B8: Belt
B9: Sunglasses
B10: Watch
B11: Scarf
B12: Hijab Accessory
B13: Other

Sheet Instructions
A1: AAYNA Product Scout Lite — How To Use
A2: Overview | B2: This sheet helps the 3 of us score and decide on products from SkyBuyBD, AliExpress, or other China sourcing platforms — fast, consistently, and without spreadsheets fights. Workflow: Whoever finds a product adds a new row and fills in the WHITE input columns only. The colored formula columns calculate themselves. Then each partner fills in the 10 score columns (or pastes in Claude's scores from the Claude Scoring Prompt tab), and the sheet tells you Buy / Maybe / Price Review / Reject automatically.
A4: Step 1 — Add the product | B4: SKU fills in automatically. Enter Date Added, Product Name, Image/Link, Category, Source Platform, Source URL, Supplier Name.
A5: Step 2 — Enter cost info | B5: Enter Unit Cost in whatever currency the supplier quoted (USD/RMB/BDT), pick the currency, then enter Shipping Cost/Unit and Misc Fees if known. Customs % and Misc Fees auto-fill from Settings tab if left blank.
A6: Step 3 — Let it calculate | B6: Unit Cost (BDT), Estimated Landed Cost, Suggested Selling Price, Expected Profit, and Profit Margin % fill in automatically.
A7: Step 4 — Score it (1 = worst, 5 = best) | B7: Feminine: how feminine/delicate does it look? Trend: how hot is this right now (TikTok/IG/competitors)? AAYNA Aesthetic Fit: how well does it match our dusty rose / cream / antique gold look? Easy to Style: how easily can a customer style this with everyday outfits? Lightweight: how light/comfortable is it to wear or carry? Reels/Photo Potential: how good would this look in a Reel, photo, or unboxing video? Giftability: how good is this as a gift? Price Fit: how comfortably can we sell this under BDT 700 and still profit? Demand: how likely is our target customer to actually want and buy this? Quality/Risk: how low is the risk of poor quality, damage in transit, or returns? Tip: use the Claude Scoring Prompt tab to get an AI first opinion on all 10 scores at once.
A8: Step 5 — Read the verdict | B8: Total Product Score (0-100) calculates automatically using the weights set in the Settings tab. Decision applies these hard rules on top of the score: if Suggested Selling Price is over BDT 700, Decision becomes 'Price Review' (and 'Reject' if it's far over, above the Hard Reject Price Ceiling in Settings); if Quality/Risk or AAYNA Aesthetic Fit score is 1 or 2, Decision can never be 'Buy' (it caps at 'Maybe') even if the total score is high. Buy = green, Maybe = yellow, Price Review = orange, Reject = red.
A9: Step 6 — Decide together | B9: Add a short Reason so the other partners know WHY. Add a Content/Reel Idea so marketing has a head start. Set Approval Status once all partners agree, note who Approved and the date.
A10: Adjusting the formulas | B10: Don't like the default markup, exchange rate, price ceilings, or scoring weights? Change them ONCE in the Settings tab — every row updates automatically. No need to touch the Product Tracker formulas.
A11: The Dashboard tab | B11: A live, read-only overview: how many products are Buy/Maybe/Price Review/Reject, the Top 10 highest scoring products, the best products under BDT 700, the best products for reels/photos, the best giftable products, and everything still waiting on partner review. Nothing on this tab needs to be filled in by hand — it reads straight from the Product Tracker tab.
A12: The Claude Scoring Prompt tab | B12: A ready-to-copy prompt for getting an AI first opinion on a product's 10 scores, a recommended decision, and a content/reel idea, formatted so the reply is easy to paste back into the right columns.
A13: Color key | B13: Green = Buy / Approved. Yellow = Maybe / Pending. Orange = Price Review (price is over our 700 BDT target but might still be worth negotiating). Red = Reject / Rejected, or a Quality/Risk or Aesthetic Fit score of 1-2.
A14: Tips for 3-partner teams | B14: Assign one score block per partner if you want speed (e.g. Partner A scores Feminine + Trend + Aesthetic Fit, Partner B scores Easy to Style + Lightweight + Reels/Photo, Partner C scores Giftability + Price Fit + Demand + Quality/Risk) — or all 3 score independently and average manually before finalizing. Keep the Reason column honest; it's your shared memory.
